,ts_recv,ts_event,rtype,publisher_id,instrument_id,action,side,price,size,channel_id,order_id,flags,ts_in_delta,sequence,symbol
1009,2022-08-26 10:59:37.217088184+00:00,2022-08-26 10:59:37.216982473+00:00,160,1,97042,A,A,4184.75,14,0,6410543150678,130,18558,35103191,ES.v.0
1010,2022-08-26 10:59:37.217399612+00:00,2022-08-26 10:59:37.217092705+00:00,160,1,97042,T,A,4184.5,7,0,6410543150679,0,19777,35103192,ES.v.0
1011,2022-08-26 10:59:37.217399612+00:00,2022-08-26 10:59:37.217092705+00:00,160,1,97042,F,B,4184.5,1,0,6410543150656,0,19777,35103192,ES.v.0
1012,2022-08-26 10:59:37.217399612+00:00,2022-08-26 10:59:37.217092705+00:00,160,1,97042,F,B,4184.5,1,0,6410543150662,0,19777,35103192,ES.v.0
1013,2022-08-26 10:59:37.217399612+00:00,2022-08-26 10:59:37.217092705+00:00,160,1,97042,F,B,4184.5,2,0,6410543150663,0,19777,35103192,ES.v.0
1014,2022-08-26 10:59:37.217399612+00:00,2022-08-26 10:59:37.217092705+00:00,160,1,97042,F,B,4184.5,1,0,6410543150665,0,19777,35103192,ES.v.0
1015,2022-08-26 10:59:37.217399612+00:00,2022-08-26 10:59:37.217092705+00:00,160,1,97042,F,B,4184.5,2,0,6410543150667,0,19777,35103192,ES.v.0
1016,2022-08-26 10:59:37.217410580+00:00,2022-08-26 10:59:37.217092705+00:00,160,1,97042,C,B,4184.5,1,0,6410543150656,0,18258,35103193,ES.v.0
1017,2022-08-26 10:59:37.217410580+00:00,2022-08-26 10:59:37.217092705+00:00,160,1,97042,C,B,4184.5,1,0,6410543150662,0,18258,35103193,ES.v.0
1018,2022-08-26 10:59:37.217410580+00:00,2022-08-26 10:59:37.217092705+00:00,160,1,97042,C,B,4184.5,2,0,6410543150663,0,18258,35103193,ES.v.0
1019,2022-08-26 10:59:37.217410580+00:00,2022-08-26 10:59:37.217092705+00:00,160,1,97042,C,B,4184.5,1,0,6410543150665,0,18258,35103193,ES.v.0
1020,2022-08-26 10:59:37.217410580+00:00,2022-08-26 10:59:37.217092705+00:00,160,1,97042,C,B,4184.5,2,0,6410543150667,130,18258,35103193,ES.v.0
1021,2022-08-26 10:59:37.217424111+00:00,2022-08-26 10:59:37.217093627+00:00,160,1,97042,A,A,4184.5,1,0,6410543150683,130,16444,35103194,ES.v.0
1022,2022-08-26 10:59:37.217443771+00:00,2022-08-26 10:59:37.217101459+00:00,160,1,97042,A,A,4184.5,1,0,6410543150686,130,17203,35103195,ES.v.0
1023,2022-08-26 10:59:37.217443771+00:00,2022-08-26 10:59:37.217101901+00:00,160,1,97042,A,A,4184.5,1,0,6410543150687,130,17203,35103195,ES.v.0
1024,2022-08-26 10:59:37.217443771+00:00,2022-08-26 10:59:37.217105549+00:00,160,1,97042,C,B,4183.25,2,0,6410543150664,130,17203,35103195,ES.v.0
1025,2022-08-26 10:59:37.217453031+00:00,2022-08-26 10:59:37.217113115+00:00,160,1,97042,A,A,4184.5,2,0,6410543150690,130,15891,35103196,ES.v.0
1026,2022-08-26 10:59:37.217463175+00:00,2022-08-26 10:59:37.217116891+00:00,160,1,97042,A,A,4184.5,1,0,6410543150692,130,17457,35103197,ES.v.0
1027,2022-08-26 10:59:37.217463175+00:00,2022-08-26 10:59:37.217121307+00:00,160,1,97042,C,B,4184.25,1,0,6410543150453,130,17457,35103197,ES.v.0
1028,2022-08-26 10:59:37.217475459+00:00,2022-08-26 10:59:37.217139007+00:00,160,1,97042,A,A,4184.75,1,0,6410543150694,130,17080,35103198,ES.v.0
1029,2022-08-26 10:59:37.217475459+00:00,2022-08-26 10:59:37.217309711+00:00,160,1,97042,A,A,4184.5,2,0,6410543150695,130,17080,35103198,ES.v.0
1030,2022-08-26 10:59:37.217475459+00:00,2022-08-26 10:59:37.217361303+00:00,160,1,97042,A,A,4184.5,1,0,6410543150696,130,17080,35103198,ES.v.0
1031,2022-08-26 10:59:37.217524083+00:00,2022-08-26 10:59:37.217369929+00:00,160,1,97042,A,A,4184.5,2,0,6410543150701,130,16753,35103199,ES.v.0
1032,2022-08-26 10:59:37.217530263+00:00,2022-08-26 10:59:37.217370627+00:00,160,1,97042,A,A,4184.5,1,0,6410543150702,130,16118,35103200,ES.v.0
1033,2022-08-26 10:59:37.217554371+00:00,2022-08-26 10:59:37.217390843+00:00,160,1,97042,C,B,4184.25,1,0,6410543150564,130,17601,35103202,ES.v.0
1034,2022-08-26 10:59:37.217611147+00:00,2022-08-26 10:59:37.217405767+00:00,160,1,97042,A,A,4184.5,1,0,6410543150708,130,16678,35103203,ES.v.0
1035,2022-08-26 10:59:37.217623359+00:00,2022-08-26 10:59:37.217418241+00:00,160,1,97042,A,A,4184.5,1,0,6410543150709,130,16853,35103205,ES.v.0
1036,2022-08-26 10:59:37.217635839+00:00,2022-08-26 10:59:37.217427503+00:00,160,1,97042,A,A,4184.5,1,0,6410543150710,130,16893,35103206,ES.v.0
1037,2022-08-26 10:59:37.217645151+00:00,2022-08-26 10:59:37.217431913+00:00,160,1,97042,C,B,4183.5,1,0,6410543150653,130,19606,35103207,ES.v.0
1038,2022-08-26 10:59:37.217650567+00:00,2022-08-26 10:59:37.217432417+00:00,160,1,97042,C,B,4183.5,1,0,6410543150643,130,15386,35103208,ES.v.0
1039,2022-08-26 10:59:37.217667699+00:00,2022-08-26 10:59:37.217470777+00:00,160,1,97042,A,A,4184.5,1,0,6410543150711,130,16421,35103210,ES.v.0
1040,2022-08-26 10:59:37.217674143+00:00,2022-08-26 10:59:37.217526143+00:00,160,1,97042,A,A,4184.5,1,0,6410543150712,130,16734,35103211,ES.v.0
1041,2022-08-26 10:59:37.217774343+00:00,2022-08-26 10:59:37.217668197+00:00,160,1,97042,A,B,4184.25,3,0,6410543150713,130,18759,35103212,ES.v.0
1042,2022-08-26 10:59:37.217782623+00:00,2022-08-26 10:59:37.217686831+00:00,160,1,97042,C,B,4184.25,1,0,6410543150323,130,17250,35103213,ES.v.0
1043,2022-08-26 10:59:37.217832619+00:00,2022-08-26 10:59:37.217737167+00:00,160,1,97042,A,B,4184.25,1,0,6410543150714,130,16294,35103214,ES.v.0
1044,2022-08-26 10:59:37.217881935+00:00,2022-08-26 10:59:37.217791213+00:00,160,1,97042,C,A,4184.5,1,0,6410543150696,130,18502,35103215,ES.v.0
1045,2022-08-26 10:59:37.218010027+00:00,2022-08-26 10:59:37.217907237+00:00,160,1,97042,A,B,4184.25,1,0,6410543150715,130,19242,35103216,ES.v.0
1046,2022-08-26 10:59:37.218120679+00:00,2022-08-26 10:59:37.218025291+00:00,160,1,97042,A,B,4184.25,2,0,6410543150716,130,18444,35103217,ES.v.0
1047,2022-08-26 10:59:37.218186950+00:00,2022-08-26 10:59:37.218104527+00:00,160,1,97042,C,B,4184.25,1,0,6410543150715,130,16154,35103218,ES.v.0
1048,2022-08-26 10:59:37.219281005+00:00,2022-08-26 10:59:37.219183377+00:00,160,1,97042,C,B,4184.25,1,0,6410543150615,130,19630,35103219,ES.v.0
1049,2022-08-26 10:59:37.219998676+00:00,2022-08-26 10:59:37.219901981+00:00,160,1,97042,C,B,4184.25,1,0,6410543150455,130,19314,35103220,ES.v.0
1050,2022-08-26 10:59:37.220032816+00:00,2022-08-26 10:59:37.219936373+00:00,160,1,97042,M,B,4184.25,2,0,6410543150713,130,16048,35103221,ES.v.0
1051,2022-08-26 10:59:37.220542983+00:00,2022-08-26 10:59:37.220455989+00:00,160,1,97042,C,B,4184.25,1,0,6410543150714,130,18416,35103222,ES.v.0
1052,2022-08-26 10:59:37.221280766+00:00,2022-08-26 10:59:37.221179061+00:00,160,1,97042,A,A,4185.5,1,0,6410543150717,130,19362,35103223,ES.v.0
1053,2022-08-26 10:59:37.232596769+00:00,2022-08-26 10:59:37.232500189+00:00,160,1,97042,A,B,4184.25,2,0,6410543150719,130,18955,35103225,ES.v.0
1054,2022-08-26 10:59:37.232694777+00:00,2022-08-26 10:59:37.232604571+00:00,160,1,97042,C,A,4184.5,2,0,6410543150701,130,18789,35103226,ES.v.0
1055,2022-08-26 10:59:37.232725461+00:00,2022-08-26 10:59:37.232641985+00:00,160,1,97042,C,A,4184.5,2,0,6410543150695,130,16617,35103227,ES.v.0
1056,2022-08-26 10:59:37.260155105+00:00,2022-08-26 10:59:37.260052293+00:00,160,1,97042,C,A,4184.5,1,0,6410543150710,130,18987,35103229,ES.v.0
1057,2022-08-26 10:59:37.260250469+00:00,2022-08-26 10:59:37.260166677+00:00,160,1,97042,C,A,4184.5,1,0,6410543150702,130,18313,35103230,ES.v.0
1058,2022-08-26 10:59:37.274420177+00:00,2022-08-26 10:59:37.274314483+00:00,160,1,97042,A,A,4185.5,1,0,6410543150720,130,18579,35103231,ES.v.0
1059,2022-08-26 10:59:37.445137896+00:00,2022-08-26 10:59:37.445013649+00:00,160,1,97042,C,A,4185.75,1,0,6410543150488,130,19602,35103232,ES.v.0
1060,2022-08-26 10:59:37.445239492+00:00,2022-08-26 10:59:37.445152917+00:00,160,1,97042,C,A,4184.5,1,0,6410543150687,130,18339,35103233,ES.v.0
1061,2022-08-26 10:59:37.445250564+00:00,2022-08-26 10:59:37.445164323+00:00,160,1,97042,C,A,4184.5,2,0,6410543150690,130,18642,35103234,ES.v.0
1062,2022-08-26 10:59:37.445257380+00:00,2022-08-26 10:59:37.445174401+00:00,160,1,97042,C,A,4184.5,1,0,6410543150686,130,16255,35103235,ES.v.0
1063,2022-08-26 10:59:37.464600896+00:00,2022-08-26 10:59:37.464491427+00:00,160,1,97042,A,A,4185.25,1,0,6410543150721,130,18801,35103236,ES.v.0
1064,2022-08-26 10:59:37.489496180+00:00,2022-08-26 10:59:37.489398595+00:00,160,1,97042,C,B,4184.25,2,0,6410543150716,130,18796,35103237,ES.v.0
1065,2022-08-26 10:59:37.504952974+00:00,2022-08-26 10:59:37.504853261+00:00,160,1,97042,C,B,4184.25,2,0,6410543150719,130,18970,35103238,ES.v.0
1066,2022-08-26 10:59:37.584566692+00:00,2022-08-26 10:59:37.584327765+00:00,160,1,97042,T,B,4184.5,1,0,6410543150722,0,18701,35103239,ES.v.0
1067,2022-08-26 10:59:37.584566692+00:00,2022-08-26 10:59:37.584327765+00:00,160,1,97042,F,A,4184.5,1,0,6410543150683,0,18701,35103239,ES.v.0
1068,2022-08-26 10:59:37.584574052+00:00,2022-08-26 10:59:37.584327765+00:00,160,1,97042,C,A,4184.5,1,0,6410543150683,130,16604,35103240,ES.v.0
1069,2022-08-26 10:59:37.584617528+00:00,2022-08-26 10:59:37.584517803+00:00,160,1,97042,A,A,4198.0,5,0,6410543150723,130,15809,35103241,ES.v.0
1070,2022-08-26 10:59:37.584801783+00:00,2022-08-26 10:59:37.584567953+00:00,160,1,97042,T,B,4184.5,2,0,6410543150724,0,18779,35103242,ES.v.0
1071,2022-08-26 10:59:37.584801783+00:00,2022-08-26 10:59:37.584567953+00:00,160,1,97042,F,A,4184.5,1,0,6410543150708,0,18779,35103242,ES.v.0
1072,2022-08-26 10:59:37.584801783+00:00,2022-08-26 10:59:37.584567953+00:00,160,1,97042,F,A,4184.5,1,0,6410543150692,0,18779,35103242,ES.v.0
1073,2022-08-26 10:59:37.584810091+00:00,2022-08-26 10:59:37.584567953+00:00,160,1,97042,C,A,4184.5,1,0,6410543150708,0,16808,35103243,ES.v.0
1074,2022-08-26 10:59:37.584810091+00:00,2022-08-26 10:59:37.584567953+00:00,160,1,97042,C,A,4184.5,1,0,6410543150692,130,16808,35103243,ES.v.0
1075,2022-08-26 10:59:37.585245675+00:00,2022-08-26 10:59:37.585153133+00:00,160,1,97042,A,B,4184.25,1,0,6410543150726,130,18613,35103244,ES.v.0
1076,2022-08-26 10:59:37.861848966+00:00,2022-08-26 10:59:37.861738071+00:00,160,1,97042,M,A,4184.75,2,0,6410543150522,130,18713,35103245,ES.v.0
1077,2022-08-26 10:59:37.869848154+00:00,2022-08-26 10:59:37.869750095+00:00,160,1,97042,A,A,4184.5,1,0,6410543150727,130,18807,35103246,ES.v.0
1078,2022-08-26 10:59:37.870081350+00:00,2022-08-26 10:59:37.869982909+00:00,160,1,97042,A,A,4184.5,1,0,6410543150728,130,18480,35103247,ES.v.0
1079,2022-08-26 10:59:37.870356733+00:00,2022-08-26 10:59:37.870265355+00:00,160,1,97042,C,A,4184.5,1,0,6410543150728,130,22396,35103248,ES.v.0
1080,2022-08-26 10:59:38.296244954+00:00,2022-08-26 10:59:38.296138421+00:00,160,1,97042,C,A,4184.5,1,0,6410543150711,130,19478,35103249,ES.v.0
1081,2022-08-26 10:59:38.314612680+00:00,2022-08-26 10:59:38.314498241+00:00,160,1,97042,A,B,4184.25,1,0,6410543150729,130,18154,35103250,ES.v.0
1082,2022-08-26 10:59:38.362859575+00:00,2022-08-26 10:59:38.362752919+00:00,160,1,97042,M,A,4184.5,1,0,6410543150598,130,18759,35103251,ES.v.0
1083,2022-08-26 10:59:39.152232397+00:00,2022-08-26 10:59:39.152097843+00:00,160,1,97042,A,B,4184.25,1,0,6410543150730,130,22639,35103252,ES.v.0
1084,2022-08-26 10:59:40.031009573+00:00,2022-08-26 10:59:40.030880057+00:00,160,1,97042,A,A,4184.5,1,0,6410543150731,130,19250,35103253,ES.v.0
1085,2022-08-26 10:59:40.051241896+00:00,2022-08-26 10:59:40.051127523+00:00,160,1,97042,A,A,4184.5,1,0,6410543150732,130,19119,35103254,ES.v.0
1086,2022-08-26 10:59:40.051248732+00:00,2022-08-26 10:59:40.051133007+00:00,160,1,97042,A,A,4184.5,2,0,6410543150733,130,17248,35103255,ES.v.0
1087,2022-08-26 10:59:40.051254468+00:00,2022-08-26 10:59:40.051147177+00:00,160,1,97042,A,A,4184.5,1,0,6410543150734,130,16769,35103256,ES.v.0
1088,2022-08-26 10:59:40.051743372+00:00,2022-08-26 10:59:40.051648589+00:00,160,1,97042,A,A,4184.5,2,0,6410543150735,130,18734,35103257,ES.v.0
1089,2022-08-26 10:59:40.136655886+00:00,2022-08-26 10:59:40.136551599+00:00,160,1,97042,A,A,4184.5,1,0,6410543150736,130,19266,35103258,ES.v.0
1090,2022-08-26 10:59:40.226392014+00:00,2022-08-26 10:59:40.226289919+00:00,160,1,97042,C,A,4184.5,1,0,6410543150736,130,18139,35103259,ES.v.0
1091,2022-08-26 10:59:40.226497394+00:00,2022-08-26 10:59:40.226408983+00:00,160,1,97042,C,A,4184.5,1,0,6410543150734,130,18518,35103260,ES.v.0
1092,2022-08-26 10:59:40.456268062+00:00,2022-08-26 10:59:40.456165605+00:00,160,1,97042,A,A,4184.5,1,0,6410543150737,130,18721,35103261,ES.v.0
1093,2022-08-26 10:59:40.456377542+00:00,2022-08-26 10:59:40.456288247+00:00,160,1,97042,A,A,4184.5,1,0,6410543150738,130,18286,35103262,ES.v.0
1094,2022-08-26 10:59:40.456394482+00:00,2022-08-26 10:59:40.456293981+00:00,160,1,97042,A,A,4184.5,1,0,6410543150739,130,16401,35103263,ES.v.0
1095,2022-08-26 10:59:40.456760841+00:00,2022-08-26 10:59:40.456667203+00:00,160,1,97042,C,B,4184.25,2,0,6410543150666,130,18324,35103264,ES.v.0
1096,2022-08-26 10:59:40.505527284+00:00,2022-08-26 10:59:40.505425875+00:00,160,1,97042,C,B,4184.25,1,0,6410543150726,130,18877,35103265,ES.v.0
1097,2022-08-26 10:59:40.505579063+00:00,2022-08-26 10:59:40.505482763+00:00,160,1,97042,A,A,4184.5,1,0,6410543150740,130,16212,35103266,ES.v.0
1098,2022-08-26 10:59:40.505585939+00:00,2022-08-26 10:59:40.505483007+00:00,160,1,97042,A,A,4184.5,1,0,6410543150741,130,16306,35103267,ES.v.0
1099,2022-08-26 10:59:40.505595315+00:00,2022-08-26 10:59:40.505483263+00:00,160,1,97042,A,A,4184.5,2,0,6410543150742,130,16484,35103268,ES.v.0
1100,2022-08-26 10:59:40.505604131+00:00,2022-08-26 10:59:40.505484645+00:00,160,1,97042,A,A,4184.5,1,0,6410543150743,130,16287,35103269,ES.v.0
1101,2022-08-26 10:59:40.505613455+00:00,2022-08-26 10:59:40.505485849+00:00,160,1,97042,A,A,4184.5,1,0,6410543150744,130,16210,35103270,ES.v.0
1102,2022-08-26 10:59:40.505634063+00:00,2022-08-26 10:59:40.505486097+00:00,160,1,97042,A,A,4184.5,1,0,6410543150745,130,18478,35103271,ES.v.0
1103,2022-08-26 10:59:40.505639907+00:00,2022-08-26 10:59:40.505495231+00:00,160,1,97042,A,A,4184.5,1,0,6410543150746,130,16191,35103272,ES.v.0
1104,2022-08-26 10:59:40.505720019+00:00,2022-08-26 10:59:40.505625999+00:00,160,1,97042,A,A,4184.5,1,0,6410543150747,130,16979,35103273,ES.v.0
1105,2022-08-26 10:59:40.506461830+00:00,2022-08-26 10:59:40.506364131+00:00,160,1,97042,C,B,4184.25,1,0,6410543150324,130,19237,35103274,ES.v.0
1106,2022-08-26 10:59:40.506580054+00:00,2022-08-26 10:59:40.506474811+00:00,160,1,97042,M,B,4184.25,1,0,6410543150459,130,18802,35103275,ES.v.0
1107,2022-08-26 10:59:40.506586486+00:00,2022-08-26 10:59:40.506479777+00:00,160,1,97042,A,A,4184.5,1,0,6410543150748,130,16367,35103276,ES.v.0
1108,2022-08-26 10:59:40.506609214+00:00,2022-08-26 10:59:40.506521671+00:00,160,1,97042,C,B,4184.25,1,0,6410543150361,130,15996,35103277,ES.v.0
1109,2022-08-26 10:59:40.506710830+00:00,2022-08-26 10:59:40.506626297+00:00,160,1,97042,C,B,4184.25,1,0,6410543150456,130,18981,35103278,ES.v.0
1110,2022-08-26 10:59:40.506740938+00:00,2022-08-26 10:59:40.506651993+00:00,160,1,97042,C,B,4184.25,1,0,6410543150616,130,16642,35103279,ES.v.0
1111,2022-08-26 10:59:40.506825338+00:00,2022-08-26 10:59:40.506733943+00:00,160,1,97042,C,B,4184.25,1,0,6410543150331,130,16585,35103281,ES.v.0
1112,2022-08-26 10:59:40.516012221+00:00,2022-08-26 10:59:40.515913071+00:00,160,1,97042,C,B,4184.25,1,0,6410543150329,130,18308,35103282,ES.v.0
1113,2022-08-26 10:59:40.516156728+00:00,2022-08-26 10:59:40.516056379+00:00,160,1,97042,M,B,4184.25,1,0,6410543150713,130,18899,35103283,ES.v.0
1114,2022-08-26 10:59:40.970618611+00:00,2022-08-26 10:59:40.970506401+00:00,160,1,97042,C,B,4184.25,1,0,6410543150386,130,19185,35103284,ES.v.0
1115,2022-08-26 10:59:40.970793043+00:00,2022-08-26 10:59:40.970704829+00:00,160,1,97042,C,B,4184.25,1,0,6410543150280,130,18637,35103285,ES.v.0
1116,2022-08-26 10:59:40.970813759+00:00,2022-08-26 10:59:40.970732549+00:00,160,1,97042,C,B,4184.25,1,0,6410543150457,130,16244,35103286,ES.v.0
1117,2022-08-26 10:59:40.970895467+00:00,2022-08-26 10:59:40.970806877+00:00,160,1,97042,C,B,4184.25,1,0,6410543150459,130,18318,35103287,ES.v.0
1118,2022-08-26 10:59:40.971136279+00:00,2022-08-26 10:59:40.971045675+00:00,160,1,97042,A,A,4184.5,1,0,6410543150749,130,18625,35103288,ES.v.0
1119,2022-08-26 10:59:40.971300059+00:00,2022-08-26 10:59:40.971212349+00:00,160,1,97042,C,B,4184.25,1,0,6410543150321,130,18859,35103289,ES.v.0
1120,2022-08-26 10:59:40.971322231+00:00,2022-08-26 10:59:40.971241071+00:00,160,1,97042,C,B,4184.25,2,0,6410543150322,130,16124,35103290,ES.v.0
1121,2022-08-26 10:59:40.971420378+00:00,2022-08-26 10:59:40.971329389+00:00,160,1,97042,C,B,4184.25,1,0,6410543150320,130,17005,35103292,ES.v.0
1122,2022-08-26 10:59:40.971426910+00:00,2022-08-26 10:59:40.971336563+00:00,160,1,97042,C,B,4184.25,1,0,6410543150572,130,16356,35103293,ES.v.0
1123,2022-08-26 10:59:40.971441906+00:00,2022-08-26 10:59:40.971349357+00:00,160,1,97042,C,B,4184.25,1,0,6410543150713,130,16232,35103294,ES.v.0
1124,2022-08-26 10:59:40.971993322+00:00,2022-08-26 10:59:40.971893475+00:00,160,1,97042,M,A,4184.75,3,0,6410543144670,130,18863,35103295,ES.v.0
1125,2022-08-26 10:59:40.972023753+00:00,2022-08-26 10:59:40.971942985+00:00,160,1,97042,C,B,4184.25,1,0,6410543150319,130,16855,35103296,ES.v.0
1126,2022-08-26 10:59:40.978543164+00:00,2022-08-26 10:59:40.978457269+00:00,160,1,97042,C,B,4184.25,2,0,6410543150286,130,18506,35103299,ES.v.0
1127,2022-08-26 10:59:41.349795262+00:00,2022-08-26 10:59:41.349688551+00:00,160,1,97042,C,B,4184.25,1,0,6410543150318,130,19096,35103300,ES.v.0
1128,2022-08-26 10:59:41.723164096+00:00,2022-08-26 10:59:41.723056179+00:00,160,1,97042,A,B,4184.25,2,0,6410543150752,130,19237,35103301,ES.v.0
1129,2022-08-26 10:59:41.723275656+00:00,2022-08-26 10:59:41.723185181+00:00,160,1,97042,C,A,4184.5,1,0,6410543150748,130,18810,35103302,ES.v.0
1130,2022-08-26 10:59:41.723977191+00:00,2022-08-26 10:59:41.723879275+00:00,160,1,97042,A,B,4184.25,1,0,6410543150753,130,19421,35103303,ES.v.0
1131,2022-08-26 10:59:41.724080495+00:00,2022-08-26 10:59:41.723990889+00:00,160,1,97042,C,A,4184.5,1,0,6410543150746,130,19182,35103304,ES.v.0
1132,2022-08-26 10:59:41.750193118+00:00,2022-08-26 10:59:41.750090935+00:00,160,1,97042,C,A,4184.5,2,0,6410543150742,130,19059,35103305,ES.v.0
1133,2022-08-26 10:59:41.861614462+00:00,2022-08-26 10:59:41.861511223+00:00,160,1,97042,C,A,4184.75,2,0,6410543150522,130,18988,35103306,ES.v.0
1134,2022-08-26 10:59:41.869513199+00:00,2022-08-26 10:59:41.869416665+00:00,160,1,97042,A,A,4184.5,1,0,6410543150754,130,18724,35103307,ES.v.0
1135,2022-08-26 10:59:41.869823735+00:00,2022-08-26 10:59:41.869735265+00:00,160,1,97042,C,B,4184.25,1,0,6410543150753,130,18326,35103308,ES.v.0
1136,2022-08-26 10:59:41.869940839+00:00,2022-08-26 10:59:41.869837383+00:00,160,1,97042,A,A,4184.5,1,0,6410543150755,130,18421,35103309,ES.v.0
1137,2022-08-26 10:59:41.870672278+00:00,2022-08-26 10:59:41.870572799+00:00,160,1,97042,A,A,4184.5,1,0,6410543150756,130,18535,35103310,ES.v.0
1138,2022-08-26 10:59:42.131622765+00:00,2022-08-26 10:59:42.131519519+00:00,160,1,97042,C,A,4184.75,1,0,6410543150503,130,18728,35103311,ES.v.0
1139,2022-08-26 10:59:42.211475019+00:00,2022-08-26 10:59:42.211375117+00:00,160,1,97042,A,A,4184.5,1,0,6410543150757,130,18651,35103312,ES.v.0
1140,2022-08-26 10:59:42.260643288+00:00,2022-08-26 10:59:42.260539767+00:00,160,1,97042,A,A,4184.75,1,0,6410543150758,130,19044,35103313,ES.v.0
1141,2022-08-26 10:59:42.573464065+00:00,2022-08-26 10:59:42.573357669+00:00,160,1,97042,A,A,4184.5,1,0,6410543150759,130,19774,35103314,ES.v.0
1142,2022-08-26 10:59:42.596064145+00:00,2022-08-26 10:59:42.595944175+00:00,160,1,97042,C,B,4184.25,2,0,6410543150620,130,18509,35103315,ES.v.0
1143,2022-08-26 10:59:42.754820670+00:00,2022-08-26 10:59:42.754109895+00:00,160,1,97042,T,B,4184.5,1,0,6410543150760,0,18327,35103316,ES.v.0
1144,2022-08-26 10:59:42.754820670+00:00,2022-08-26 10:59:42.754109895+00:00,160,1,97042,F,A,4184.5,1,0,6410543150709,0,18327,35103316,ES.v.0
1145,2022-08-26 10:59:42.754827722+00:00,2022-08-26 10:59:42.754109895+00:00,160,1,97042,C,A,4184.5,1,0,6410543150709,130,16554,35103317,ES.v.0
1146,2022-08-26 10:59:42.754932902+00:00,2022-08-26 10:59:42.754829505+00:00,160,1,97042,A,B,4184.25,1,0,6410543150761,130,18304,35103318,ES.v.0
1147,2022-08-26 10:59:42.755932325+00:00,2022-08-26 10:59:42.755833329+00:00,160,1,97042,A,B,4184.25,1,0,6410543150762,130,18652,35103319,ES.v.0
1148,2022-08-26 10:59:42.829279796+00:00,2022-08-26 10:59:42.829161781+00:00,160,1,97042,C,B,4184.25,1,0,6410543150762,130,19072,35103320,ES.v.0
1149,2022-08-26 10:59:42.829604995+00:00,2022-08-26 10:59:42.829513347+00:00,160,1,97042,C,B,4184.25,1,0,6410543150761,130,18550,35103321,ES.v.0
1150,2022-08-26 10:59:42.964386415+00:00,2022-08-26 10:59:42.964181621+00:00,160,1,97042,T,B,4184.5,1,0,6410543150764,0,18454,35103322,ES.v.0
1151,2022-08-26 10:59:42.964386415+00:00,2022-08-26 10:59:42.964181621+00:00,160,1,97042,F,A,4184.5,1,0,6410543150712,0,18454,35103322,ES.v.0
1152,2022-08-26 10:59:42.964393659+00:00,2022-08-26 10:59:42.964181621+00:00,160,1,97042,C,A,4184.5,1,0,6410543150712,130,16538,35103323,ES.v.0
1153,2022-08-26 10:59:43.252594755+00:00,2022-08-26 10:59:43.252496885+00:00,160,1,97042,A,A,4194.5,1,0,6410543150771,130,18218,35103326,ES.v.0
1154,2022-08-26 10:59:43.653151150+00:00,2022-08-26 10:59:43.653053023+00:00,160,1,97042,A,B,4184.25,1,0,6410543150772,130,19938,35103327,ES.v.0
1155,2022-08-26 10:59:43.936223470+00:00,2022-08-26 10:59:43.936109663+00:00,160,1,97042,A,B,4184.25,1,0,6410543150774,130,19850,35103328,ES.v.0
1156,2022-08-26 10:59:44.098685480+00:00,2022-08-26 10:59:44.098571177+00:00,160,1,97042,M,B,4183.75,1,0,6410543068665,130,19354,35103329,ES.v.0
1157,2022-08-26 10:59:44.150275982+00:00,2022-08-26 10:59:44.150170555+00:00,160,1,97042,A,B,4183.5,1,0,6410543150775,130,19110,35103330,ES.v.0
1158,2022-08-26 10:59:44.165314280+00:00,2022-08-26 10:59:44.165207089+00:00,160,1,97042,M,B,4183.75,1,0,6410543068681,130,18676,35103331,ES.v.0
1159,2022-08-26 10:59:44.165861540+00:00,2022-08-26 10:59:44.165770799+00:00,160,1,97042,M,B,4183.75,1,0,6410543068683,130,18555,35103332,ES.v.0
1160,2022-08-26 10:59:44.166322635+00:00,2022-08-26 10:59:44.166231577+00:00,160,1,97042,M,B,4183.75,1,0,6410543068688,130,18849,35103333,ES.v.0
1161,2022-08-26 10:59:44.486724977+00:00,2022-08-26 10:59:44.486617345+00:00,160,1,97042,C,B,4184.25,1,0,6410543150774,130,19460,35103334,ES.v.0
1162,2022-08-26 10:59:44.522621350+00:00,2022-08-26 10:59:44.522515637+00:00,160,1,97042,A,B,4184.25,1,0,6410543150776,130,18222,35103335,ES.v.0
1163,2022-08-26 10:59:44.522732086+00:00,2022-08-26 10:59:44.522641933+00:00,160,1,97042,C,A,4184.5,1,0,6410543150755,130,18231,35103336,ES.v.0
1164,2022-08-26 10:59:44.590477966+00:00,2022-08-26 10:59:44.590372643+00:00,160,1,97042,A,B,4183.75,1,0,6410543150777,130,18426,35103337,ES.v.0
1165,2022-08-26 10:59:44.629573938+00:00,2022-08-26 10:59:44.629464137+00:00,160,1,97042,M,B,4184.0,2,0,6410543143634,130,18236,35103338,ES.v.0
1166,2022-08-26 10:59:44.640598970+00:00,2022-08-26 10:59:44.640488835+00:00,160,1,97042,C,B,4181.25,1,0,6410543148521,130,18498,35103339,ES.v.0
1167,2022-08-26 10:59:45.130615496+00:00,2022-08-26 10:59:45.130509665+00:00,160,1,97042,C,B,4184.25,1,0,6410543150776,130,18592,35103340,ES.v.0
1168,2022-08-26 10:59:45.130848872+00:00,2022-08-26 10:59:45.130748151+00:00,160,1,97042,A,A,4184.5,2,0,6410543150778,130,18528,35103341,ES.v.0
1169,2022-08-26 10:59:45.130968055+00:00,2022-08-26 10:59:45.130861409+00:00,160,1,97042,A,A,4184.5,1,0,6410543150779,130,18408,35103342,ES.v.0
1170,2022-08-26 10:59:45.206241276+00:00,2022-08-26 10:59:45.206138367+00:00,160,1,97042,C,A,4184.5,2,0,6410543150778,130,18923,35103343,ES.v.0
1171,2022-08-26 10:59:46.099160646+00:00,2022-08-26 10:59:46.099048279+00:00,160,1,97042,A,B,4184.25,1,0,6410543150781,130,18779,35103344,ES.v.0
1172,2022-08-26 10:59:46.099284810+00:00,2022-08-26 10:59:46.099188309+00:00,160,1,97042,A,B,4184.25,1,0,6410543150782,130,18819,35103345,ES.v.0
1173,2022-08-26 10:59:46.099466914+00:00,2022-08-26 10:59:46.099376657+00:00,160,1,97042,C,A,4184.5,1,0,6410543150739,130,18227,35103346,ES.v.0
1174,2022-08-26 10:59:46.099775685+00:00,2022-08-26 10:59:46.099686821+00:00,160,1,97042,A,B,4184.25,1,0,6410543150783,130,18304,35103347,ES.v.0
1175,2022-08-26 10:59:46.124446150+00:00,2022-08-26 10:59:46.124344107+00:00,160,1,97042,C,B,4184.25,1,0,6410543150783,130,18631,35103348,ES.v.0
1176,2022-08-26 10:59:46.377831686+00:00,2022-08-26 10:59:46.377722947+00:00,160,1,97042,A,A,4185.25,1,0,6410543150784,130,18931,35103349,ES.v.0
1177,2022-08-26 10:59:46.386374490+00:00,2022-08-26 10:59:46.386281663+00:00,160,1,97042,C,B,4184.25,1,0,6410543150781,130,18786,35103350,ES.v.0
1178,2022-08-26 10:59:46.386487190+00:00,2022-08-26 10:59:46.386401291+00:00,160,1,97042,C,B,4184.25,1,0,6410543150782,130,18261,35103351,ES.v.0
1179,2022-08-26 10:59:46.544577436+00:00,2022-08-26 10:59:46.544474021+00:00,160,1,97042,A,B,4184.25,1,0,6410543150785,130,18364,35103352,ES.v.0
1180,2022-08-26 10:59:46.783886414+00:00,2022-08-26 10:59:46.783776755+00:00,160,1,97042,A,B,4184.25,2,0,6410543150786,130,18867,35103353,ES.v.0
1181,2022-08-26 10:59:46.783892469+00:00,2022-08-26 10:59:46.783782367+00:00,160,1,97042,A,B,4184.25,1,0,6410543150787,130,16398,35103354,ES.v.0
1182,2022-08-26 10:59:46.783998922+00:00,2022-08-26 10:59:46.783909161+00:00,160,1,97042,A,B,4184.25,1,0,6410543150788,130,18795,35103355,ES.v.0
1183,2022-08-26 10:59:46.784073441+00:00,2022-08-26 10:59:46.783983875+00:00,160,1,97042,A,B,4184.25,2,0,6410543150789,130,16483,35103356,ES.v.0
1184,2022-08-26 10:59:46.784133853+00:00,2022-08-26 10:59:46.784041199+00:00,160,1,97042,A,B,4184.25,1,0,6410543150790,130,18661,35103357,ES.v.0
1185,2022-08-26 10:59:46.784140953+00:00,2022-08-26 10:59:46.784046599+00:00,160,1,97042,C,A,4184.5,1,0,6410543150741,130,16749,35103358,ES.v.0
1186,2022-08-26 10:59:46.784245345+00:00,2022-08-26 10:59:46.784149727+00:00,160,1,97042,A,B,4184.25,1,0,6410543150791,130,18219,35103359,ES.v.0
1187,2022-08-26 10:59:46.784288929+00:00,2022-08-26 10:59:46.784201131+00:00,160,1,97042,C,A,4184.5,1,0,6410543150738,130,16206,35103360,ES.v.0
1188,2022-08-26 10:59:46.800590002+00:00,2022-08-26 10:59:46.800468955+00:00,160,1,97042,M,A,4285.75,11,0,6410543144670,130,19109,35103361,ES.v.0
1189,2022-08-26 10:59:46.800689277+00:00,2022-08-26 10:59:46.800598399+00:00,160,1,97042,A,B,4184.25,1,0,6410543150792,130,18182,35103362,ES.v.0
1190,2022-08-26 10:59:46.800694870+00:00,2022-08-26 10:59:46.800598827+00:00,160,1,97042,C,A,4184.5,1,0,6410543150745,130,15952,35103363,ES.v.0
1191,2022-08-26 10:59:46.800804602+00:00,2022-08-26 10:59:46.800705603+00:00,160,1,97042,C,A,4184.5,2,0,6410543150735,130,18586,35103364,ES.v.0
1192,2022-08-26 10:59:46.800815449+00:00,2022-08-26 10:59:46.800709007+00:00,160,1,97042,C,A,4184.5,1,0,6410543150740,130,16092,35103365,ES.v.0
1193,2022-08-26 10:59:46.800904453+00:00,2022-08-26 10:59:46.800817479+00:00,160,1,97042,C,A,4184.5,1,0,6410543150743,130,18723,35103366,ES.v.0
1194,2022-08-26 10:59:46.800987657+00:00,2022-08-26 10:59:46.800899117+00:00,160,1,97042,A,B,4184.25,1,0,6410543150793,130,16404,35103367,ES.v.0
1195,2022-08-26 10:59:46.801165921+00:00,2022-08-26 10:59:46.801072027+00:00,160,1,97042,A,B,4184.25,1,0,6410543150794,130,18785,35103368,ES.v.0
1196,2022-08-26 10:59:46.801234501+00:00,2022-08-26 10:59:46.801148559+00:00,160,1,97042,C,A,4184.5,1,0,6410543150749,130,17232,35103369,ES.v.0
1197,2022-08-26 10:59:46.801268845+00:00,2022-08-26 10:59:46.801172999+00:00,160,1,97042,C,A,4184.5,1,0,6410543150744,130,18284,35103370,ES.v.0
1198,2022-08-26 10:59:46.801303249+00:00,2022-08-26 10:59:46.801222389+00:00,160,1,97042,C,A,4184.5,1,0,6410543150737,130,16230,35103371,ES.v.0
1199,2022-08-26 10:59:46.801326801+00:00,2022-08-26 10:59:46.801242419+00:00,160,1,97042,A,B,4184.25,1,0,6410543150795,130,16101,35103372,ES.v.0
1200,2022-08-26 10:59:46.801335433+00:00,2022-08-26 10:59:46.801247699+00:00,160,1,97042,C,A,4184.5,2,0,6410543150733,130,16413,35103373,ES.v.0
1201,2022-08-26 10:59:46.801665764+00:00,2022-08-26 10:59:46.801344707+00:00,160,1,97042,T,B,4184.5,10,0,6410543150796,0,19214,35103374,ES.v.0
1202,2022-08-26 10:59:46.801665764+00:00,2022-08-26 10:59:46.801344707+00:00,160,1,97042,F,A,4184.5,1,0,6410543150727,0,19214,35103374,ES.v.0
1203,2022-08-26 10:59:46.801665764+00:00,2022-08-26 10:59:46.801344707+00:00,160,1,97042,F,A,4184.5,1,0,6410543150598,0,19214,35103374,ES.v.0
1204,2022-08-26 10:59:46.801665764+00:00,2022-08-26 10:59:46.801344707+00:00,160,1,97042,F,A,4184.5,1,0,6410543150731,0,19214,35103374,ES.v.0
1205,2022-08-26 10:59:46.801665764+00:00,2022-08-26 10:59:46.801344707+00:00,160,1,97042,F,A,4184.5,1,0,6410543150732,0,19214,35103374,ES.v.0
1206,2022-08-26 10:59:46.801665764+00:00,2022-08-26 10:59:46.801344707+00:00,160,1,97042,F,A,4184.5,1,0,6410543150747,0,19214,35103374,ES.v.0
1207,2022-08-26 10:59:46.801665764+00:00,2022-08-26 10:59:46.801344707+00:00,160,1,97042,F,A,4184.5,1,0,6410543150754,0,19214,35103374,ES.v.0
1208,2022-08-26 10:59:46.801665764+00:00,2022-08-26 10:59:46.801344707+00:00,160,1,97042,F,A,4184.5,1,0,6410543150756,0,19214,35103374,ES.v.0
1209,2022-08-26 10:59:46.801665764+00:00,2022-08-26 10:59:46.801344707+00:00,160,1,97042,F,A,4184.5,1,0,6410543150757,0,19214,35103374,ES.v.0
1210,2022-08-26 10:59:46.801665764+00:00,2022-08-26 10:59:46.801344707+00:00,160,1,97042,F,A,4184.5,1,0,6410543150759,0,19214,35103374,ES.v.0
1211,2022-08-26 10:59:46.801665764+00:00,2022-08-26 10:59:46.801344707+00:00,160,1,97042,F,A,4184.5,1,0,6410543150779,0,19214,35103374,ES.v.0
1212,2022-08-26 10:59:46.801676720+00:00,2022-08-26 10:59:46.801344707+00:00,160,1,97042,C,A,4184.5,1,0,6410543150727,0,19241,35103375,ES.v.0
1213,2022-08-26 10:59:46.801676720+00:00,2022-08-26 10:59:46.801344707+00:00,160,1,97042,C,A,4184.5,1,0,6410543150598,0,19241,35103375,ES.v.0
1214,2022-08-26 10:59:46.801676720+00:00,2022-08-26 10:59:46.801344707+00:00,160,1,97042,C,A,4184.5,1,0,6410543150731,0,19241,35103375,ES.v.0
1215,2022-08-26 10:59:46.801676720+00:00,2022-08-26 10:59:46.801344707+00:00,160,1,97042,C,A,4184.5,1,0,6410543150732,0,19241,35103375,ES.v.0
1216,2022-08-26 10:59:46.801676720+00:00,2022-08-26 10:59:46.801344707+00:00,160,1,97042,C,A,4184.5,1,0,6410543150747,0,19241,35103375,ES.v.0
1217,2022-08-26 10:59:46.801676720+00:00,2022-08-26 10:59:46.801344707+00:00,160,1,97042,C,A,4184.5,1,0,6410543150754,0,19241,35103375,ES.v.0
1218,2022-08-26 10:59:46.801676720+00:00,2022-08-26 10:59:46.801344707+00:00,160,1,97042,C,A,4184.5,1,0,6410543150756,0,19241,35103375,ES.v.0
1219,2022-08-26 10:59:46.801676720+00:00,2022-08-26 10:59:46.801344707+00:00,160,1,97042,C,A,4184.5,1,0,6410543150757,0,19241,35103375,ES.v.0
1220,2022-08-26 10:59:46.801676720+00:00,2022-08-26 10:59:46.801344707+00:00,160,1,97042,C,A,4184.5,1,0,6410543150759,0,19241,35103375,ES.v.0
1221,2022-08-26 10:59:46.801676720+00:00,2022-08-26 10:59:46.801344707+00:00,160,1,97042,C,A,4184.5,1,0,6410543150779,130,19241,35103375,ES.v.0
1222,2022-08-26 10:59:46.801676720+00:00,2022-08-26 10:59:46.801557055+00:00,160,1,97042,A,B,4184.25,1,0,6410543150797,130,19241,35103375,ES.v.0
1223,2022-08-26 10:59:46.801706456+00:00,2022-08-26 10:59:46.801612863+00:00,160,1,97042,A,B,4184.5,1,0,6410543150799,130,15589,35103376,ES.v.0
1224,2022-08-26 10:59:46.801726296+00:00,2022-08-26 10:59:46.801617593+00:00,160,1,97042,A,B,4184.25,1,0,6410543150800,130,16113,35103378,ES.v.0
1225,2022-08-26 10:59:46.801750100+00:00,2022-08-26 10:59:46.801644927+00:00,160,1,97042,A,B,4184.5,1,0,6410543150802,130,15663,35103379,ES.v.0
1226,2022-08-26 10:59:46.801788644+00:00,2022-08-26 10:59:46.801669247+00:00,160,1,97042,A,B,4184.5,1,0,6410543150803,130,18863,35103380,ES.v.0
1227,2022-08-26 10:59:46.801841940+00:00,2022-08-26 10:59:46.801672203+00:00,160,1,97042,A,B,4184.5,1,0,6410543150808,130,15471,35103381,ES.v.0
1228,2022-08-26 10:59:46.801910660+00:00,2022-08-26 10:59:46.801702189+00:00,160,1,97042,A,B,4184.25,2,0,6410543150813,130,15722,35103384,ES.v.0
1229,2022-08-26 10:59:46.801917044+00:00,2022-08-26 10:59:46.801705841+00:00,160,1,97042,A,B,4184.25,1,0,6410543150814,130,15841,35103385,ES.v.0
1230,2022-08-26 10:59:46.801922072+00:00,2022-08-26 10:59:46.801714841+00:00,160,1,97042,C,A,4185.5,1,0,6410543150720,130,15318,35103386,ES.v.0
1231,2022-08-26 10:59:46.801948532+00:00,2022-08-26 10:59:46.801715039+00:00,160,1,97042,M,A,4244.0,5,0,6410543150717,130,16862,35103387,ES.v.0
1232,2022-08-26 10:59:46.801964828+00:00,2022-08-26 10:59:46.801719825+00:00,160,1,97042,A,B,4184.25,1,0,6410543150815,130,15705,35103389,ES.v.0
1233,2022-08-26 10:59:46.801970628+00:00,2022-08-26 10:59:46.801726691+00:00,160,1,97042,A,B,4184.25,1,0,6410543150816,130,15382,35103390,ES.v.0
1234,2022-08-26 10:59:46.801976744+00:00,2022-08-26 10:59:46.801754219+00:00,160,1,97042,A,B,4184.25,1,0,6410543150817,130,16245,35103391,ES.v.0
1235,2022-08-26 10:59:46.801990412+00:00,2022-08-26 10:59:46.801807325+00:00,160,1,97042,A,B,4183.25,2,0,6410543150818,130,18651,35103392,ES.v.0
1236,2022-08-26 10:59:46.801996764+00:00,2022-08-26 10:59:46.801866779+00:00,160,1,97042,A,B,4184.5,1,0,6410543150819,130,16115,35103393,ES.v.0
1237,2022-08-26 10:59:46.802216227+00:00,2022-08-26 10:59:46.802124671+00:00,160,1,97042,A,B,4184.25,1,0,6410543150820,130,18692,35103394,ES.v.0
1238,2022-08-26 10:59:46.802325895+00:00,2022-08-26 10:59:46.802220605+00:00,160,1,97042,M,B,4184.0,4,0,6410543140923,130,19034,35103395,ES.v.0
1239,2022-08-26 10:59:46.820958249+00:00,2022-08-26 10:59:46.820850273+00:00,160,1,97042,A,B,4172.0,1,0,6410543150822,130,18496,35103398,ES.v.0
1240,2022-08-26 10:59:46.836152759+00:00,2022-08-26 10:59:46.836045417+00:00,160,1,97042,C,B,4184.25,1,0,6410543150814,130,16621,35103403,ES.v.0
1241,2022-08-26 10:59:46.890106178+00:00,2022-08-26 10:59:46.889870273+00:00,160,1,97042,T,A,4184.5,1,0,6410543150825,0,18767,35103404,ES.v.0
1242,2022-08-26 10:59:46.890106178+00:00,2022-08-26 10:59:46.889870273+00:00,160,1,97042,F,B,4184.5,1,0,6410543150799,0,18767,35103404,ES.v.0
1243,2022-08-26 10:59:46.890113738+00:00,2022-08-26 10:59:46.889870273+00:00,160,1,97042,C,B,4184.5,1,0,6410543150799,130,16383,35103405,ES.v.0
1244,2022-08-26 10:59:46.890297038+00:00,2022-08-26 10:59:46.890096099+00:00,160,1,97042,T,A,4184.5,1,0,6410543150827,0,19057,35103407,ES.v.0
1245,2022-08-26 10:59:46.890297038+00:00,2022-08-26 10:59:46.890096099+00:00,160,1,97042,F,B,4184.5,1,0,6410543150802,0,19057,35103407,ES.v.0
1246,2022-08-26 10:59:46.890304729+00:00,2022-08-26 10:59:46.890096099+00:00,160,1,97042,C,B,4184.5,1,0,6410543150802,130,16692,35103408,ES.v.0
1247,2022-08-26 10:59:46.890326081+00:00,2022-08-26 10:59:46.890112971+00:00,160,1,97042,C,B,4184.5,1,0,6410543150808,130,15952,35103409,ES.v.0
1248,2022-08-26 10:59:46.890432409+00:00,2022-08-26 10:59:46.890124951+00:00,160,1,97042,T,A,4184.5,2,0,6410543150832,0,19325,35103410,ES.v.0
1249,2022-08-26 10:59:46.890432409+00:00,2022-08-26 10:59:46.890124951+00:00,160,1,97042,F,B,4184.5,1,0,6410543150803,0,19325,35103410,ES.v.0
1250,2022-08-26 10:59:46.890432409+00:00,2022-08-26 10:59:46.890124951+00:00,160,1,97042,F,B,4184.5,1,0,6410543150819,0,19325,35103410,ES.v.0
1251,2022-08-26 10:59:46.890442865+00:00,2022-08-26 10:59:46.890124951+00:00,160,1,97042,C,B,4184.5,1,0,6410543150803,0,17761,35103411,ES.v.0
1252,2022-08-26 10:59:46.890442865+00:00,2022-08-26 10:59:46.890124951+00:00,160,1,97042,C,B,4184.5,1,0,6410543150819,130,17761,35103411,ES.v.0
1253,2022-08-26 10:59:46.890442865+00:00,2022-08-26 10:59:46.890130237+00:00,160,1,97042,C,B,4183.25,2,0,6410543150818,130,17761,35103411,ES.v.0
1254,2022-08-26 10:59:46.890452693+00:00,2022-08-26 10:59:46.890168535+00:00,160,1,97042,A,A,4184.75,1,0,6410543150834,130,16400,35103412,ES.v.0
1255,2022-08-26 10:59:46.890452693+00:00,2022-08-26 10:59:46.890220193+00:00,160,1,97042,C,B,4184.25,1,0,6410543150815,130,16400,35103412,ES.v.0
1256,2022-08-26 10:59:46.890452693+00:00,2022-08-26 10:59:46.890221001+00:00,160,1,97042,C,B,4184.25,1,0,6410543150820,130,16400,35103412,ES.v.0
1257,2022-08-26 10:59:46.890551017+00:00,2022-08-26 10:59:46.890433035+00:00,160,1,97042,A,A,4184.5,1,0,6410543150837,130,19224,35103413,ES.v.0
1258,2022-08-26 10:59:46.890566957+00:00,2022-08-26 10:59:46.890460311+00:00,160,1,97042,C,B,4184.25,2,0,6410543150813,130,15657,35103415,ES.v.0
1259,2022-08-26 10:59:46.890585985+00:00,2022-08-26 10:59:46.890494449+00:00,160,1,97042,C,A,4184.75,1,0,6410543150834,130,16007,35103416,ES.v.0
1260,2022-08-26 10:59:46.890766133+00:00,2022-08-26 10:59:46.890562799+00:00,160,1,97042,T,B,4184.5,1,0,6410543150838,0,18761,35103417,ES.v.0
1261,2022-08-26 10:59:46.890766133+00:00,2022-08-26 10:59:46.890562799+00:00,160,1,97042,F,A,4184.5,1,0,6410543150837,0,18761,35103417,ES.v.0
1262,2022-08-26 10:59:46.890781697+00:00,2022-08-26 10:59:46.890562799+00:00,160,1,97042,C,A,4184.5,1,0,6410543150837,130,19284,35103418,ES.v.0
1263,2022-08-26 10:59:46.890781697+00:00,2022-08-26 10:59:46.890617351+00:00,160,1,97042,A,B,4184.25,1,0,6410543150839,130,19284,35103418,ES.v.0
1264,2022-08-26 10:59:46.890781697+00:00,2022-08-26 10:59:46.890637883+00:00,160,1,97042,A,B,4184.25,1,0,6410543150840,130,19284,35103418,ES.v.0
1265,2022-08-26 10:59:46.890781697+00:00,2022-08-26 10:59:46.890654701+00:00,160,1,97042,A,B,4184.25,1,0,6410543150841,130,19284,35103418,ES.v.0
1266,2022-08-26 10:59:46.890781697+00:00,2022-08-26 10:59:46.890659547+00:00,160,1,97042,A,B,4184.25,1,0,6410543150842,130,19284,35103418,ES.v.0
1267,2022-08-26 10:59:46.890786037+00:00,2022-08-26 10:59:46.890691359+00:00,160,1,97042,A,B,4184.25,1,0,6410543150843,130,16165,35103419,ES.v.0
1268,2022-08-26 10:59:46.890792401+00:00,2022-08-26 10:59:46.890693819+00:00,160,1,97042,A,B,4184.25,1,0,6410543150844,130,16594,35103420,ES.v.0
1269,2022-08-26 10:59:46.890882340+00:00,2022-08-26 10:59:46.890755609+00:00,160,1,97042,A,B,4184.5,1,0,6410543150845,130,16689,35103422,ES.v.0
1270,2022-08-26 10:59:46.890889477+00:00,2022-08-26 10:59:46.890766763+00:00,160,1,97042,A,B,4184.5,1,0,6410543150846,130,17187,35103423,ES.v.0
1271,2022-08-26 10:59:46.890931013+00:00,2022-08-26 10:59:46.890773567+00:00,160,1,97042,A,B,4184.5,1,0,6410543150849,130,19275,35103424,ES.v.0
1272,2022-08-26 10:59:46.890963804+00:00,2022-08-26 10:59:46.890805439+00:00,160,1,97042,M,B,4184.25,3,0,6410543141440,130,16579,35103426,ES.v.0
1273,2022-08-26 10:59:46.890970357+00:00,2022-08-26 10:59:46.890862321+00:00,160,1,97042,A,B,4184.25,1,0,6410543150851,130,16144,35103427,ES.v.0
1274,2022-08-26 10:59:46.891041340+00:00,2022-08-26 10:59:46.890947861+00:00,160,1,97042,A,B,4183.25,2,0,6410543150852,130,16212,35103428,ES.v.0
1275,2022-08-26 10:59:46.891155480+00:00,2022-08-26 10:59:46.891062317+00:00,160,1,97042,M,B,4083.75,12,0,6410543141440,130,18508,35103429,ES.v.0
1276,2022-08-26 10:59:46.891243164+00:00,2022-08-26 10:59:46.891155543+00:00,160,1,97042,A,B,4184.25,2,0,6410543150853,130,16138,35103430,ES.v.0
1277,2022-08-26 10:59:46.932355861+00:00,2022-08-26 10:59:46.932249525+00:00,160,1,97042,A,B,4183.5,1,0,6410543150856,130,19013,35103433,ES.v.0
1278,2022-08-26 10:59:46.932466273+00:00,2022-08-26 10:59:46.932368519+00:00,160,1,97042,A,B,4184.5,2,0,6410543150857,130,18403,35103434,ES.v.0
1279,2022-08-26 10:59:46.932577133+00:00,2022-08-26 10:59:46.932491795+00:00,160,1,97042,A,B,4184.5,2,0,6410543150858,130,16180,35103436,ES.v.0
1280,2022-08-26 10:59:46.932797917+00:00,2022-08-26 10:59:46.932711189+00:00,160,1,97042,C,B,4184.5,1,0,6410543150849,130,18638,35103437,ES.v.0
1281,2022-08-26 10:59:46.934385658+00:00,2022-08-26 10:59:46.934291695+00:00,160,1,97042,C,B,4184.5,2,0,6410543150858,130,18886,35103438,ES.v.0
1282,2022-08-26 10:59:46.934492870+00:00,2022-08-26 10:59:46.934401113+00:00,160,1,97042,C,B,4183.25,2,0,6410543150852,130,18567,35103439,ES.v.0
1283,2022-08-26 10:59:46.985421037+00:00,2022-08-26 10:59:46.985313835+00:00,160,1,97042,A,B,4183.5,1,0,6410543150859,130,18528,35103440,ES.v.0
1284,2022-08-26 10:59:47.246838464+00:00,2022-08-26 10:59:47.246735119+00:00,160,1,97042,A,B,4183.5,1,0,6410543150861,130,20814,35103442,ES.v.0
1285,2022-08-26 10:59:47.284373270+00:00,2022-08-26 10:59:47.284265699+00:00,160,1,97042,A,B,4184.5,2,0,6410543150862,130,18249,35103443,ES.v.0
1286,2022-08-26 10:59:47.284490238+00:00,2022-08-26 10:59:47.284390925+00:00,160,1,97042,A,B,4183.25,2,0,6410543150863,130,18407,35103444,ES.v.0
1287,2022-08-26 10:59:47.515953986+00:00,2022-08-26 10:59:47.515854801+00:00,160,1,97042,C,B,4179.75,1,0,6410542685848,130,18308,35103445,ES.v.0
1288,2022-08-26 10:59:47.618434488+00:00,2022-08-26 10:59:47.618333885+00:00,160,1,97042,A,B,4182.0,1,0,6410543150864,130,20255,35103446,ES.v.0
1289,2022-08-26 10:59:47.721556038+00:00,2022-08-26 10:59:47.721454733+00:00,160,1,97042,A,B,4184.5,1,0,6410543150865,130,20229,35103447,ES.v.0
1290,2022-08-26 10:59:47.742341548+00:00,2022-08-26 10:59:47.742039517+00:00,160,1,97042,T,A,4184.5,7,0,6410543150866,0,20702,35103448,ES.v.0
1291,2022-08-26 10:59:47.742341548+00:00,2022-08-26 10:59:47.742039517+00:00,160,1,97042,F,B,4184.5,1,0,6410543150845,0,20702,35103448,ES.v.0
1292,2022-08-26 10:59:47.742341548+00:00,2022-08-26 10:59:47.742039517+00:00,160,1,97042,F,B,4184.5,1,0,6410543150846,0,20702,35103448,ES.v.0
1293,2022-08-26 10:59:47.742341548+00:00,2022-08-26 10:59:47.742039517+00:00,160,1,97042,F,B,4184.5,2,0,6410543150857,0,20702,35103448,ES.v.0
1294,2022-08-26 10:59:47.742341548+00:00,2022-08-26 10:59:47.742039517+00:00,160,1,97042,F,B,4184.5,2,0,6410543150862,0,20702,35103448,ES.v.0
1295,2022-08-26 10:59:47.742341548+00:00,2022-08-26 10:59:47.742039517+00:00,160,1,97042,F,B,4184.5,1,0,6410543150865,0,20702,35103448,ES.v.0
1296,2022-08-26 10:59:47.742353460+00:00,2022-08-26 10:59:47.742039517+00:00,160,1,97042,C,B,4184.5,1,0,6410543150845,0,20050,35103449,ES.v.0
1297,2022-08-26 10:59:47.742353460+00:00,2022-08-26 10:59:47.742039517+00:00,160,1,97042,C,B,4184.5,1,0,6410543150846,0,20050,35103449,ES.v.0
1298,2022-08-26 10:59:47.742353460+00:00,2022-08-26 10:59:47.742039517+00:00,160,1,97042,C,B,4184.5,2,0,6410543150857,0,20050,35103449,ES.v.0
1299,2022-08-26 10:59:47.742353460+00:00,2022-08-26 10:59:47.742039517+00:00,160,1,97042,C,B,4184.5,2,0,6410543150862,0,20050,35103449,ES.v.0
1300,2022-08-26 10:59:47.742353460+00:00,2022-08-26 10:59:47.742039517+00:00,160,1,97042,C,B,4184.5,1,0,6410543150865,130,20050,35103449,ES.v.0
1301,2022-08-26 10:59:47.742380212+00:00,2022-08-26 10:59:47.742266725+00:00,160,1,97042,A,A,4184.5,1,0,6410543150870,130,19483,35103450,ES.v.0
1302,2022-08-26 10:59:47.742403840+00:00,2022-08-26 10:59:47.742300863+00:00,160,1,97042,A,A,4184.5,2,0,6410543150871,130,19004,35103451,ES.v.0
1303,2022-08-26 10:59:47.742412788+00:00,2022-08-26 10:59:47.742302885+00:00,160,1,97042,A,A,4184.5,1,0,6410543150872,130,18525,35103452,ES.v.0
1304,2022-08-26 10:59:47.742528052+00:00,2022-08-26 10:59:47.742356555+00:00,160,1,97042,A,A,4184.5,1,0,6410543150881,130,15587,35103454,ES.v.0
1305,2022-08-26 10:59:47.742534924+00:00,2022-08-26 10:59:47.742369335+00:00,160,1,97042,C,B,4183.25,2,0,6410543150863,130,16263,35103455,ES.v.0
1306,2022-08-26 10:59:47.742555484+00:00,2022-08-26 10:59:47.742388797+00:00,160,1,97042,C,B,4183.5,1,0,6410543150859,130,19006,35103456,ES.v.0
1307,2022-08-26 10:59:47.742560500+00:00,2022-08-26 10:59:47.742389181+00:00,160,1,97042,C,B,4183.5,1,0,6410543150856,130,16107,35103457,ES.v.0
1308,2022-08-26 10:59:47.742691275+00:00,2022-08-26 10:59:47.742391005+00:00,160,1,97042,T,B,4184.5,1,0,6410543150882,0,19036,35103458,ES.v.0
1309,2022-08-26 10:59:47.742691275+00:00,2022-08-26 10:59:47.742391005+00:00,160,1,97042,F,A,4184.5,1,0,6410543150870,0,19036,35103458,ES.v.0
1310,2022-08-26 10:59:47.742748407+00:00,2022-08-26 10:59:47.742391005+00:00,160,1,97042,C,A,4184.5,1,0,6410543150870,130,20862,35103459,ES.v.0
1311,2022-08-26 10:59:47.742748407+00:00,2022-08-26 10:59:47.742413937+00:00,160,1,97042,T,B,4184.5,2,0,6410543150883,0,20862,35103459,ES.v.0
1312,2022-08-26 10:59:47.742748407+00:00,2022-08-26 10:59:47.742413937+00:00,160,1,97042,F,A,4184.5,2,0,6410543150871,0,20862,35103459,ES.v.0
1313,2022-08-26 10:59:47.742748407+00:00,2022-08-26 10:59:47.742413937+00:00,160,1,97042,C,A,4184.5,2,0,6410543150871,130,20862,35103459,ES.v.0
1314,2022-08-26 10:59:47.742748407+00:00,2022-08-26 10:59:47.742420617+00:00,160,1,97042,A,A,4184.5,1,0,6410543150884,130,20862,35103459,ES.v.0
1315,2022-08-26 10:59:47.742748407+00:00,2022-08-26 10:59:47.742458347+00:00,160,1,97042,A,B,4184.25,1,0,6410543150885,130,20862,35103459,ES.v.0
1316,2022-08-26 10:59:47.742748407+00:00,2022-08-26 10:59:47.742500987+00:00,160,1,97042,A,B,4184.25,1,0,6410543150886,130,20862,35103459,ES.v.0
1317,2022-08-26 10:59:47.742748407+00:00,2022-08-26 10:59:47.742541877+00:00,160,1,97042,A,B,4184.25,1,0,6410543150887,130,20862,35103459,ES.v.0
1318,2022-08-26 10:59:47.742750279+00:00,2022-08-26 10:59:47.742609395+00:00,160,1,97042,A,B,4184.25,1,0,6410543150888,130,15216,35103460,ES.v.0
1319,2022-08-26 10:59:47.742761879+00:00,2022-08-26 10:59:47.742669427+00:00,160,1,97042,A,B,4184.25,1,0,6410543150889,130,16142,35103461,ES.v.0
1320,2022-08-26 10:59:47.742920999+00:00,2022-08-26 10:59:47.742697521+00:00,160,1,97042,T,B,4184.5,2,0,6410543150890,0,19745,35103463,ES.v.0
1321,2022-08-26 10:59:47.742920999+00:00,2022-08-26 10:59:47.742697521+00:00,160,1,97042,F,A,4184.5,1,0,6410543150872,0,19745,35103463,ES.v.0
1322,2022-08-26 10:59:47.742920999+00:00,2022-08-26 10:59:47.742697521+00:00,160,1,97042,F,A,4184.5,1,0,6410543150884,0,19745,35103463,ES.v.0
1323,2022-08-26 10:59:47.742932399+00:00,2022-08-26 10:59:47.742697521+00:00,160,1,97042,C,A,4184.5,1,0,6410543150872,0,17662,35103464,ES.v.0
1324,2022-08-26 10:59:47.742932399+00:00,2022-08-26 10:59:47.742697521+00:00,160,1,97042,C,A,4184.5,1,0,6410543150884,0,17662,35103464,ES.v.0
1325,2022-08-26 10:59:47.742932399+00:00,2022-08-26 10:59:47.742697521+00:00,160,1,97042,C,A,4184.5,1,0,6410543150881,130,17662,35103464,ES.v.0
1326,2022-08-26 10:59:47.742932399+00:00,2022-08-26 10:59:47.742713521+00:00,160,1,97042,A,B,4184.5,1,0,6410543150891,130,17662,35103464,ES.v.0
1327,2022-08-26 10:59:47.742940647+00:00,2022-08-26 10:59:47.742736951+00:00,160,1,97042,A,B,4184.5,1,0,6410543150893,130,16525,35103465,ES.v.0
1328,2022-08-26 10:59:47.742951239+00:00,2022-08-26 10:59:47.742753457+00:00,160,1,97042,A,B,4184.5,1,0,6410543150895,130,16287,35103466,ES.v.0
1329,2022-08-26 10:59:47.742966851+00:00,2022-08-26 10:59:47.742783369+00:00,160,1,97042,C,B,4184.25,1,0,6410543150886,130,16963,35103467,ES.v.0
1330,2022-08-26 10:59:47.742973979+00:00,2022-08-26 10:59:47.742831561+00:00,160,1,97042,C,B,4184.25,1,0,6410543150885,130,15405,35103468,ES.v.0
1331,2022-08-26 10:59:47.743184363+00:00,2022-08-26 10:59:47.742931413+00:00,160,1,97042,T,A,4184.5,2,0,6410543150903,0,18704,35103469,ES.v.0
1332,2022-08-26 10:59:47.743184363+00:00,2022-08-26 10:59:47.742931413+00:00,160,1,97042,F,B,4184.5,1,0,6410543150891,0,18704,35103469,ES.v.0
1333,2022-08-26 10:59:47.743184363+00:00,2022-08-26 10:59:47.742931413+00:00,160,1,97042,F,B,4184.5,1,0,6410543150893,0,18704,35103469,ES.v.0
1334,2022-08-26 10:59:47.743198283+00:00,2022-08-26 10:59:47.742931413+00:00,160,1,97042,C,B,4184.5,1,0,6410543150891,0,19004,35103470,ES.v.0
1335,2022-08-26 10:59:47.743198283+00:00,2022-08-26 10:59:47.742931413+00:00,160,1,97042,C,B,4184.5,1,0,6410543150893,130,19004,35103470,ES.v.0
1336,2022-08-26 10:59:47.743198283+00:00,2022-08-26 10:59:47.742938837+00:00,160,1,97042,A,B,4183.25,2,0,6410543150904,130,19004,35103470,ES.v.0
1337,2022-08-26 10:59:47.743198283+00:00,2022-08-26 10:59:47.742995283+00:00,160,1,97042,A,B,4184.5,2,0,6410543150905,130,19004,35103470,ES.v.0
1338,2022-08-26 10:59:47.743198283+00:00,2022-08-26 10:59:47.743013543+00:00,160,1,97042,A,B,4184.25,2,0,6410543150906,130,19004,35103470,ES.v.0
1339,2022-08-26 10:59:47.743390335+00:00,2022-08-26 10:59:47.743189191+00:00,160,1,97042,T,A,4184.5,1,0,6410543150909,0,18822,35103472,ES.v.0
1340,2022-08-26 10:59:47.743390335+00:00,2022-08-26 10:59:47.743189191+00:00,160,1,97042,F,B,4184.5,1,0,6410543150895,0,18822,35103472,ES.v.0
1341,2022-08-26 10:59:47.743399979+00:00,2022-08-26 10:59:47.743189191+00:00,160,1,97042,C,B,4184.5,1,0,6410543150895,130,17239,35103473,ES.v.0
1342,2022-08-26 10:59:47.743399979+00:00,2022-08-26 10:59:47.743204157+00:00,160,1,97042,C,B,4184.5,2,0,6410543150905,130,17239,35103473,ES.v.0
1343,2022-08-26 10:59:47.743426366+00:00,2022-08-26 10:59:47.743332461+00:00,160,1,97042,C,B,4184.25,2,0,6410543150853,130,17064,35103474,ES.v.0
1344,2022-08-26 10:59:47.743532950+00:00,2022-08-26 10:59:47.743444659+00:00,160,1,97042,A,A,4184.75,2,0,6410543150912,130,18311,35103475,ES.v.0
1345,2022-08-26 10:59:47.743641982+00:00,2022-08-26 10:59:47.743555703+00:00,160,1,97042,C,A,4184.75,2,0,6410543150912,130,18601,35103476,ES.v.0
1346,2022-08-26 10:59:47.743974478+00:00,2022-08-26 10:59:47.743885091+00:00,160,1,97042,C,B,4184.25,2,0,6410543150906,130,19408,35103477,ES.v.0
1347,2022-08-26 10:59:47.875649091+00:00,2022-08-26 10:59:47.875529609+00:00,160,1,97042,A,A,4185.75,1,0,6410543150915,130,20112,35103480,ES.v.0
1348,2022-08-26 10:59:47.928328684+00:00,2022-08-26 10:59:47.928221381+00:00,160,1,97042,A,B,4183.5,1,0,6410543150916,130,18569,35103481,ES.v.0
1349,2022-08-26 10:59:47.928334512+00:00,2022-08-26 10:59:47.928222711+00:00,160,1,97042,A,A,4185.5,1,0,6410543150917,130,16265,35103482,ES.v.0
1350,2022-08-26 10:59:47.981416477+00:00,2022-08-26 10:59:47.981314029+00:00,160,1,97042,A,B,4183.5,1,0,6410543150919,130,19410,35103483,ES.v.0
1351,2022-08-26 10:59:47.981422812+00:00,2022-08-26 10:59:47.981315103+00:00,160,1,97042,A,A,4185.5,1,0,6410543150920,130,16328,35103484,ES.v.0
1352,2022-08-26 10:59:47.992822636+00:00,2022-08-26 10:59:47.992719069+00:00,160,1,97042,A,A,4185.0,1,0,6410543150921,130,18603,35103485,ES.v.0
1353,2022-08-26 10:59:48.841006441+00:00,2022-08-26 10:59:48.840762707+00:00,160,1,97042,T,B,4184.75,1,0,6410543150923,0,19245,35103486,ES.v.0
1354,2022-08-26 10:59:48.841006441+00:00,2022-08-26 10:59:48.840762707+00:00,160,1,97042,F,A,4184.75,1,0,6410543140820,0,19245,35103486,ES.v.0
1355,2022-08-26 10:59:48.841013237+00:00,2022-08-26 10:59:48.840762707+00:00,160,1,97042,C,A,4184.75,1,0,6410543140820,130,16290,35103487,ES.v.0
1356,2022-08-26 10:59:48.841086757+00:00,2022-08-26 10:59:48.840985315+00:00,160,1,97042,A,B,4184.5,2,0,6410543150924,130,16138,35103488,ES.v.0
1357,2022-08-26 10:59:48.841095257+00:00,2022-08-26 10:59:48.840986007+00:00,160,1,97042,A,B,4184.5,1,0,6410543150925,130,16849,35103489,ES.v.0
1358,2022-08-26 10:59:48.841107473+00:00,2022-08-26 10:59:48.840988151+00:00,160,1,97042,A,B,4184.5,2,0,6410543150926,130,18111,35103490,ES.v.0
1359,2022-08-26 10:59:48.841134625+00:00,2022-08-26 10:59:48.841041757+00:00,160,1,97042,C,B,4183.25,2,0,6410543150904,130,16178,35103491,ES.v.0
1360,2022-08-26 10:59:48.841182185+00:00,2022-08-26 10:59:48.841094535+00:00,160,1,97042,C,A,4185.5,1,0,6410543150920,130,16133,35103492,ES.v.0
1361,2022-08-26 10:59:48.841188665+00:00,2022-08-26 10:59:48.841094681+00:00,160,1,97042,C,A,4185.5,1,0,6410543150917,130,16490,35103493,ES.v.0
1362,2022-08-26 10:59:48.841216069+00:00,2022-08-26 10:59:48.841125537+00:00,160,1,97042,A,B,4184.5,1,0,6410543150927,130,16102,35103495,ES.v.0
1363,2022-08-26 10:59:48.841326877+00:00,2022-08-26 10:59:48.841231929+00:00,160,1,97042,A,B,4183.25,2,0,6410543150928,130,18875,35103496,ES.v.0
1364,2022-08-26 10:59:48.841391245+00:00,2022-08-26 10:59:48.841306129+00:00,160,1,97042,A,B,4184.25,2,0,6410543150929,130,16317,35103497,ES.v.0
1365,2022-08-26 10:59:49.009143723+00:00,2022-08-26 10:59:49.009032687+00:00,160,1,97042,A,A,4185.25,1,0,6410543150931,130,18573,35103500,ES.v.0
1366,2022-08-26 10:59:49.221560442+00:00,2022-08-26 10:59:49.221457067+00:00,160,1,97042,A,A,4185.25,1,0,6410543150932,130,19220,35103501,ES.v.0
1367,2022-08-26 10:59:49.236609760+00:00,2022-08-26 10:59:49.236294543+00:00,160,1,97042,T,B,4184.75,6,0,6410543150933,0,20233,35103502,ES.v.0
1368,2022-08-26 10:59:49.236609760+00:00,2022-08-26 10:59:49.236294543+00:00,160,1,97042,F,A,4184.75,1,0,6410543140821,0,20233,35103502,ES.v.0
1369,2022-08-26 10:59:49.236609760+00:00,2022-08-26 10:59:49.236294543+00:00,160,1,97042,F,A,4184.75,1,0,6410543140830,0,20233,35103502,ES.v.0
1370,2022-08-26 10:59:49.236609760+00:00,2022-08-26 10:59:49.236294543+00:00,160,1,97042,F,A,4184.75,1,0,6410543140834,0,20233,35103502,ES.v.0
1371,2022-08-26 10:59:49.236609760+00:00,2022-08-26 10:59:49.236294543+00:00,160,1,97042,F,A,4184.75,1,0,6410543140844,0,20233,35103502,ES.v.0
1372,2022-08-26 10:59:49.236609760+00:00,2022-08-26 10:59:49.236294543+00:00,160,1,97042,F,A,4184.75,1,0,6410543140845,0,20233,35103502,ES.v.0
1373,2022-08-26 10:59:49.236609760+00:00,2022-08-26 10:59:49.236294543+00:00,160,1,97042,F,A,4184.75,1,0,6410543140848,0,20233,35103502,ES.v.0
1374,2022-08-26 10:59:49.236621476+00:00,2022-08-26 10:59:49.236294543+00:00,160,1,97042,C,A,4184.75,1,0,6410543140821,0,18457,35103503,ES.v.0
1375,2022-08-26 10:59:49.236621476+00:00,2022-08-26 10:59:49.236294543+00:00,160,1,97042,C,A,4184.75,1,0,6410543140830,0,18457,35103503,ES.v.0
1376,2022-08-26 10:59:49.236621476+00:00,2022-08-26 10:59:49.236294543+00:00,160,1,97042,C,A,4184.75,1,0,6410543140834,0,18457,35103503,ES.v.0
1377,2022-08-26 10:59:49.236621476+00:00,2022-08-26 10:59:49.236294543+00:00,160,1,97042,C,A,4184.75,1,0,6410543140844,0,18457,35103503,ES.v.0
1378,2022-08-26 10:59:49.236621476+00:00,2022-08-26 10:59:49.236294543+00:00,160,1,97042,C,A,4184.75,1,0,6410543140845,0,18457,35103503,ES.v.0
1379,2022-08-26 10:59:49.236621476+00:00,2022-08-26 10:59:49.236294543+00:00,160,1,97042,C,A,4184.75,1,0,6410543140848,130,18457,35103503,ES.v.0
1380,2022-08-26 10:59:49.236621476+00:00,2022-08-26 10:59:49.236503745+00:00,160,1,97042,C,A,4184.75,1,0,6410543150530,130,18457,35103503,ES.v.0
1381,2022-08-26 10:59:49.236621476+00:00,2022-08-26 10:59:49.236504935+00:00,160,1,97042,A,B,4184.5,1,0,6410543150934,130,18457,35103503,ES.v.0
1382,2022-08-26 10:59:49.236657376+00:00,2022-08-26 10:59:49.236551927+00:00,160,1,97042,A,B,4184.5,1,0,6410543150936,130,15351,35103505,ES.v.0
1383,2022-08-26 10:59:49.236686164+00:00,2022-08-26 10:59:49.236589847+00:00,160,1,97042,A,B,4184.5,1,0,6410543150937,130,16188,35103506,ES.v.0
1384,2022-08-26 10:59:49.236754064+00:00,2022-08-26 10:59:49.236614911+00:00,160,1,97042,A,B,4184.5,2,0,6410543150942,130,16059,35103507,ES.v.0
1385,2022-08-26 10:59:49.236785876+00:00,2022-08-26 10:59:49.236680117+00:00,160,1,97042,A,B,4184.5,1,0,6410543150943,130,16845,35103508,ES.v.0
1386,2022-08-26 10:59:49.236849496+00:00,2022-08-26 10:59:49.236759925+00:00,160,1,97042,C,B,4184.5,1,0,6410543150936,130,18343,35103509,ES.v.0
1387,2022-08-26 10:59:49.236856300+00:00,2022-08-26 10:59:49.236760361+00:00,160,1,97042,C,A,4185.0,1,0,6410543150531,130,16077,35103510,ES.v.0
1388,2022-08-26 10:59:49.237023920+00:00,2022-08-26 10:59:49.236935231+00:00,160,1,97042,A,B,4184.5,2,0,6410543150944,130,18572,35103511,ES.v.0
1389,2022-08-26 10:59:49.237030160+00:00,2022-08-26 10:59:49.236948069+00:00,160,1,97042,C,B,4184.5,2,0,6410543150942,130,16229,35103512,ES.v.0
1390,2022-08-26 10:59:49.237140620+00:00,2022-08-26 10:59:49.237042877+00:00,160,1,97042,A,B,4184.5,1,0,6410543150945,130,19279,35103513,ES.v.0
1391,2022-08-26 10:59:49.246684814+00:00,2022-08-26 10:59:49.246589117+00:00,160,1,97042,A,A,4203.25,1,0,6410543150947,130,18546,35103515,ES.v.0
1392,2022-08-26 10:59:49.257021099+00:00,2022-08-26 10:59:49.256902637+00:00,160,1,97042,A,A,4200.0,1,0,6410543150948,130,18642,35103516,ES.v.0
1393,2022-08-26 10:59:49.587141536+00:00,2022-08-26 10:59:49.587031931+00:00,160,1,97042,A,B,4184.5,1,0,6410543150949,130,20751,35103517,ES.v.0
1394,2022-08-26 10:59:49.587148088+00:00,2022-08-26 10:59:49.587032373+00:00,160,1,97042,C,A,4184.75,1,0,6410543150523,130,16467,35103518,ES.v.0
1395,2022-08-26 10:59:49.587251951+00:00,2022-08-26 10:59:49.587163269+00:00,160,1,97042,A,B,4184.5,1,0,6410543150950,130,18631,35103519,ES.v.0
1396,2022-08-26 10:59:49.587292579+00:00,2022-08-26 10:59:49.587206283+00:00,160,1,97042,C,A,4184.75,1,0,6410543150694,130,15882,35103520,ES.v.0
1397,2022-08-26 10:59:49.587456799+00:00,2022-08-26 10:59:49.587369811+00:00,160,1,97042,C,B,4184.25,1,0,6410543150843,130,18814,35103521,ES.v.0
1398,2022-08-26 10:59:49.587473735+00:00,2022-08-26 10:59:49.587388513+00:00,160,1,97042,C,B,4184.25,1,0,6410543150844,130,16039,35103522,ES.v.0
1399,2022-08-26 10:59:49.587494207+00:00,2022-08-26 10:59:49.587416051+00:00,160,1,97042,C,B,4184.25,1,0,6410543150800,130,15922,35103523,ES.v.0
1400,2022-08-26 10:59:49.587517775+00:00,2022-08-26 10:59:49.587438035+00:00,160,1,97042,C,B,4184.25,1,0,6410543150816,130,16008,35103524,ES.v.0
1401,2022-08-26 10:59:49.602651993+00:00,2022-08-26 10:59:49.602552423+00:00,160,1,97042,C,B,4184.5,1,0,6410543150950,130,18499,35103525,ES.v.0
1402,2022-08-26 10:59:49.613267949+00:00,2022-08-26 10:59:49.613047113+00:00,160,1,97042,T,B,4184.75,1,0,6410543150951,0,18400,35103526,ES.v.0
1403,2022-08-26 10:59:49.613267949+00:00,2022-08-26 10:59:49.613047113+00:00,160,1,97042,F,A,4184.75,1,0,6410543140849,0,18400,35103526,ES.v.0
1404,2022-08-26 10:59:49.613274569+00:00,2022-08-26 10:59:49.613047113+00:00,160,1,97042,C,A,4184.75,1,0,6410543140849,130,16158,35103527,ES.v.0
1405,2022-08-26 10:59:49.613382797+00:00,2022-08-26 10:59:49.613293789+00:00,160,1,97042,A,B,4184.5,1,0,6410543150952,130,18707,35103528,ES.v.0
1406,2022-08-26 10:59:50.450470047+00:00,2022-08-26 10:59:50.450356383+00:00,160,1,97042,A,B,4182.75,2,0,6410543150953,130,18858,35103529,ES.v.0
1407,2022-08-26 10:59:50.503689751+00:00,2022-08-26 10:59:50.503577775+00:00,160,1,97042,M,A,4185.5,1,0,6410543150921,130,18709,35103530,ES.v.0
1408,2022-08-26 10:59:50.543099798+00:00,2022-08-26 10:59:50.542976491+00:00,160,1,97042,A,B,4184.5,2,0,6410543150954,130,18805,35103531,ES.v.0
1409,2022-08-26 10:59:50.543105966+00:00,2022-08-26 10:59:50.542976675+00:00,160,1,97042,A,B,4184.5,1,0,6410543150955,130,16303,35103532,ES.v.0
1410,2022-08-26 10:59:50.543111698+00:00,2022-08-26 10:59:50.542978057+00:00,160,1,97042,C,A,4184.75,1,0,6410543150535,130,16160,35103533,ES.v.0
1411,2022-08-26 10:59:50.543117806+00:00,2022-08-26 10:59:50.542986883+00:00,160,1,97042,A,B,4184.5,1,0,6410543150956,130,16297,35103534,ES.v.0
1412,2022-08-26 10:59:50.543223698+00:00,2022-08-26 10:59:50.543121243+00:00,160,1,97042,A,B,4184.5,1,0,6410543150957,130,18056,35103535,ES.v.0
1413,2022-08-26 10:59:50.543229746+00:00,2022-08-26 10:59:50.543122811+00:00,160,1,97042,C,A,4184.75,1,0,6410543150498,130,16179,35103536,ES.v.0
1414,2022-08-26 10:59:50.543247446+00:00,2022-08-26 10:59:50.543137621+00:00,160,1,97042,C,A,4184.75,1,0,6410543150560,130,16219,35103537,ES.v.0
1415,2022-08-26 10:59:50.543253178+00:00,2022-08-26 10:59:50.543160159+00:00,160,1,97042,C,B,4184.25,1,0,6410543150840,130,16025,35103538,ES.v.0
1416,2022-08-26 10:59:50.543258534+00:00,2022-08-26 10:59:50.543171949+00:00,160,1,97042,C,B,4184.25,1,0,6410543150839,130,15935,35103539,ES.v.0
1417,2022-08-26 10:59:50.543273954+00:00,2022-08-26 10:59:50.543187437+00:00,160,1,97042,C,B,4184.25,1,0,6410543150797,130,16117,35103540,ES.v.0
1418,2022-08-26 10:59:50.543346910+00:00,2022-08-26 10:59:50.543255915+00:00,160,1,97042,C,A,4184.75,1,0,6410543141643,130,18218,35103541,ES.v.0
1419,2022-08-26 10:59:50.543576953+00:00,2022-08-26 10:59:50.543485141+00:00,160,1,97042,A,B,4184.5,1,0,6410543150958,130,18137,35103542,ES.v.0
1420,2022-08-26 10:59:50.543835285+00:00,2022-08-26 10:59:50.543743401+00:00,160,1,97042,A,B,4184.5,1,0,6410543150959,130,22578,35103544,ES.v.0
1421,2022-08-26 10:59:50.543849581+00:00,2022-08-26 10:59:50.543763689+00:00,160,1,97042,A,B,4184.5,1,0,6410543150960,130,16620,35103545,ES.v.0
1422,2022-08-26 10:59:50.543939905+00:00,2022-08-26 10:59:50.543850113+00:00,160,1,97042,A,B,4184.5,1,0,6410543150961,130,18309,35103546,ES.v.0
1423,2022-08-26 10:59:50.543964289+00:00,2022-08-26 10:59:50.543868251+00:00,160,1,97042,M,A,4199.75,2,0,6410542732926,130,16154,35103547,ES.v.0
1424,2022-08-26 10:59:50.544119613+00:00,2022-08-26 10:59:50.544028561+00:00,160,1,97042,A,B,4184.5,1,0,6410543150962,130,18408,35103548,ES.v.0
1425,2022-08-26 10:59:50.544172965+00:00,2022-08-26 10:59:50.544089975+00:00,160,1,97042,C,B,4184.25,1,0,6410543150841,130,16059,35103549,ES.v.0
1426,2022-08-26 10:59:50.544289873+00:00,2022-08-26 10:59:50.544180931+00:00,160,1,97042,C,B,4184.25,1,0,6410543150842,130,18349,35103550,ES.v.0
1427,2022-08-26 10:59:50.544433880+00:00,2022-08-26 10:59:50.544185787+00:00,160,1,97042,T,B,4184.75,3,0,6410543150963,0,18335,35103551,ES.v.0
1428,2022-08-26 10:59:50.544433880+00:00,2022-08-26 10:59:50.544185787+00:00,160,1,97042,F,A,4184.75,2,0,6410543140896,0,18335,35103551,ES.v.0
1429,2022-08-26 10:59:50.544433880+00:00,2022-08-26 10:59:50.544185787+00:00,160,1,97042,F,A,4184.75,1,0,6410543142913,0,18335,35103551,ES.v.0
1430,2022-08-26 10:59:50.544450320+00:00,2022-08-26 10:59:50.544185787+00:00,160,1,97042,C,A,4184.75,2,0,6410543140896,0,19504,35103552,ES.v.0
1431,2022-08-26 10:59:50.544450320+00:00,2022-08-26 10:59:50.544185787+00:00,160,1,97042,M,A,4184.75,1,0,6410543142913,130,19504,35103552,ES.v.0
1432,2022-08-26 10:59:50.544450320+00:00,2022-08-26 10:59:50.544188303+00:00,160,1,97042,C,B,4184.25,1,0,6410543150851,130,19504,35103552,ES.v.0
1433,2022-08-26 10:59:50.544450320+00:00,2022-08-26 10:59:50.544214197+00:00,160,1,97042,A,B,4184.5,1,0,6410543150964,130,19504,35103552,ES.v.0
1434,2022-08-26 10:59:50.544450320+00:00,2022-08-26 10:59:50.544218799+00:00,160,1,97042,M,B,4184.5,2,0,6410543150962,130,19504,35103552,ES.v.0
1435,2022-08-26 10:59:50.544450320+00:00,2022-08-26 10:59:50.544245377+00:00,160,1,97042,A,B,4184.5,1,0,6410543150965,130,19504,35103552,ES.v.0
1436,2022-08-26 10:59:50.544450320+00:00,2022-08-26 10:59:50.544290719+00:00,160,1,97042,C,A,4184.75,1,0,6410543150677,130,19504,35103552,ES.v.0
1437,2022-08-26 10:59:50.544450320+00:00,2022-08-26 10:59:50.544325377+00:00,160,1,97042,C,A,4184.75,2,0,6410543150515,130,19504,35103552,ES.v.0
1438,2022-08-26 10:59:50.544453716+00:00,2022-08-26 10:59:50.544348997+00:00,160,1,97042,A,B,4184.5,1,0,6410543150966,130,16369,35103553,ES.v.0
1439,2022-08-26 10:59:50.544482064+00:00,2022-08-26 10:59:50.544383961+00:00,160,1,97042,A,B,4184.5,1,0,6410543150967,130,16269,35103554,ES.v.0
1440,2022-08-26 10:59:50.544494468+00:00,2022-08-26 10:59:50.544395357+00:00,160,1,97042,M,B,4184.5,1,0,6410543150887,130,16273,35103555,ES.v.0
1441,2022-08-26 10:59:50.544664680+00:00,2022-08-26 10:59:50.544438443+00:00,160,1,97042,T,B,4184.75,2,0,6410543150968,0,18792,35103556,ES.v.0
1442,2022-08-26 10:59:50.544664680+00:00,2022-08-26 10:59:50.544438443+00:00,160,1,97042,F,A,4184.75,1,0,6410543142913,0,18792,35103556,ES.v.0
1443,2022-08-26 10:59:50.544664680+00:00,2022-08-26 10:59:50.544438443+00:00,160,1,97042,F,A,4184.75,1,0,6410543143163,0,18792,35103556,ES.v.0
1444,2022-08-26 10:59:50.544675452+00:00,2022-08-26 10:59:50.544438443+00:00,160,1,97042,C,A,4184.75,1,0,6410543142913,0,16922,35103557,ES.v.0
1445,2022-08-26 10:59:50.544675452+00:00,2022-08-26 10:59:50.544438443+00:00,160,1,97042,C,A,4184.75,1,0,6410543143163,130,16922,35103557,ES.v.0
1446,2022-08-26 10:59:50.544746948+00:00,2022-08-26 10:59:50.544438613+00:00,160,1,97042,T,B,4184.75,11,0,6410543150969,0,16251,35103558,ES.v.0
1447,2022-08-26 10:59:50.544746948+00:00,2022-08-26 10:59:50.544438613+00:00,160,1,97042,F,A,4184.75,1,0,6410543149165,0,16251,35103558,ES.v.0
1448,2022-08-26 10:59:50.544746948+00:00,2022-08-26 10:59:50.544438613+00:00,160,1,97042,F,A,4184.75,1,0,6410543149896,0,16251,35103558,ES.v.0
1449,2022-08-26 10:59:50.544746948+00:00,2022-08-26 10:59:50.544438613+00:00,160,1,97042,F,A,4184.75,1,0,6410543150313,0,16251,35103558,ES.v.0
1450,2022-08-26 10:59:50.544746948+00:00,2022-08-26 10:59:50.544438613+00:00,160,1,97042,F,A,4184.75,1,0,6410543150676,0,16251,35103558,ES.v.0
1451,2022-08-26 10:59:50.544746948+00:00,2022-08-26 10:59:50.544438613+00:00,160,1,97042,F,A,4184.75,7,0,6410543150678,0,16251,35103558,ES.v.0
1452,2022-08-26 10:59:50.544805832+00:00,2022-08-26 10:59:50.544438613+00:00,160,1,97042,C,A,4184.75,1,0,6410543149165,0,27323,35103559,ES.v.0
1453,2022-08-26 10:59:50.544805832+00:00,2022-08-26 10:59:50.544438613+00:00,160,1,97042,C,A,4184.75,1,0,6410543149896,0,27323,35103559,ES.v.0
1454,2022-08-26 10:59:50.544805832+00:00,2022-08-26 10:59:50.544438613+00:00,160,1,97042,C,A,4184.75,1,0,6410543150313,0,27323,35103559,ES.v.0
1455,2022-08-26 10:59:50.544805832+00:00,2022-08-26 10:59:50.544438613+00:00,160,1,97042,C,A,4184.75,1,0,6410543150676,0,27323,35103559,ES.v.0
1456,2022-08-26 10:59:50.544805832+00:00,2022-08-26 10:59:50.544438613+00:00,160,1,97042,C,A,4184.75,1,0,6410543150524,0,27323,35103559,ES.v.0
1457,2022-08-26 10:59:50.544805832+00:00,2022-08-26 10:59:50.544438613+00:00,160,1,97042,M,A,4184.75,7,0,6410543150678,130,27323,35103559,ES.v.0
1458,2022-08-26 10:59:50.544805832+00:00,2022-08-26 10:59:50.544447077+00:00,160,1,97042,T,B,4184.75,1,0,6410543150970,0,27323,35103559,ES.v.0
1459,2022-08-26 10:59:50.544805832+00:00,2022-08-26 10:59:50.544447077+00:00,160,1,97042,F,A,4184.75,1,0,6410543150678,0,27323,35103559,ES.v.0
1460,2022-08-26 10:59:50.544805832+00:00,2022-08-26 10:59:50.544447077+00:00,160,1,97042,M,A,4184.75,6,0,6410543150678,130,27323,35103559,ES.v.0
1461,2022-08-26 10:59:50.544805832+00:00,2022-08-26 10:59:50.544479645+00:00,160,1,97042,C,B,4184.25,1,0,6410543150889,130,27323,35103559,ES.v.0
1462,2022-08-26 10:59:50.544805832+00:00,2022-08-26 10:59:50.544488393+00:00,160,1,97042,A,B,4184.5,1,0,6410543150971,130,27323,35103559,ES.v.0
1463,2022-08-26 10:59:50.544805832+00:00,2022-08-26 10:59:50.544495389+00:00,160,1,97042,A,B,4184.5,1,0,6410543150972,130,27323,35103559,ES.v.0
1464,2022-08-26 10:59:50.544805832+00:00,2022-08-26 10:59:50.544504465+00:00,160,1,97042,M,A,4197.75,1,0,6410542878648,130,27323,35103559,ES.v.0
1465,2022-08-26 10:59:50.544805832+00:00,2022-08-26 10:59:50.544563671+00:00,160,1,97042,C,B,4184.5,1,0,6410543150966,130,27323,35103559,ES.v.0
1466,2022-08-26 10:59:50.544880884+00:00,2022-08-26 10:59:50.544655011+00:00,160,1,97042,T,B,4184.75,1,0,6410543150973,0,19691,35103560,ES.v.0
1467,2022-08-26 10:59:50.544880884+00:00,2022-08-26 10:59:50.544655011+00:00,160,1,97042,F,A,4184.75,1,0,6410543150678,0,19691,35103560,ES.v.0
1468,2022-08-26 10:59:50.544880884+00:00,2022-08-26 10:59:50.544655011+00:00,160,1,97042,M,A,4184.75,5,0,6410543150678,130,19691,35103560,ES.v.0
1469,2022-08-26 10:59:50.544927788+00:00,2022-08-26 10:59:50.544657523+00:00,160,1,97042,T,B,4184.75,1,0,6410543150974,0,21362,35103561,ES.v.0
1470,2022-08-26 10:59:50.544927788+00:00,2022-08-26 10:59:50.544657523+00:00,160,1,97042,F,A,4184.75,1,0,6410543150678,0,21362,35103561,ES.v.0
1471,2022-08-26 10:59:50.544927788+00:00,2022-08-26 10:59:50.544657523+00:00,160,1,97042,M,A,4184.75,4,0,6410543150678,130,21362,35103561,ES.v.0
1472,2022-08-26 10:59:50.544927788+00:00,2022-08-26 10:59:50.544657779+00:00,160,1,97042,T,B,4184.75,1,0,6410543150975,0,21362,35103561,ES.v.0
1473,2022-08-26 10:59:50.544927788+00:00,2022-08-26 10:59:50.544657779+00:00,160,1,97042,F,A,4184.75,1,0,6410543150678,0,21362,35103561,ES.v.0
1474,2022-08-26 10:59:50.544927788+00:00,2022-08-26 10:59:50.544657779+00:00,160,1,97042,M,A,4184.75,3,0,6410543150678,130,21362,35103561,ES.v.0
1475,2022-08-26 10:59:50.545075499+00:00,2022-08-26 10:59:50.544670695+00:00,160,1,97042,T,B,4184.75,4,0,6410543150980,0,18563,35103562,ES.v.0
1476,2022-08-26 10:59:50.545075499+00:00,2022-08-26 10:59:50.544670695+00:00,160,1,97042,F,A,4184.75,3,0,6410543150678,0,18563,35103562,ES.v.0
1477,2022-08-26 10:59:50.545075499+00:00,2022-08-26 10:59:50.544670695+00:00,160,1,97042,F,A,4184.75,1,0,6410543150758,0,18563,35103562,ES.v.0
1478,2022-08-26 10:59:50.545093643+00:00,2022-08-26 10:59:50.544670695+00:00,160,1,97042,C,A,4184.75,3,0,6410543150678,0,19421,35103563,ES.v.0
